Workbook
Name adequacy: Metric_Codes!$C$45:$C$49
Name authority: Metric_Codes!$C$57:$C$60
Name confidence: Metric_Codes!$C$96:$C$98
Name decision: Metric_Codes!$C$69:$C$71
Name experience: Metric_Codes!$C$72:$C$76
Name ins_imp: #REF!
Name Insurance: Metric_Codes!$C$99:$C$103
Name Insurance_Role: Metric_Codes!$C$50:$C$52
Name Magnitude: Metric_Codes!$C$3:$C$7
Name participation: Metric_Codes!$C$66:$C$68
Name Preparedness: Metric_Codes!$C$61:$C$65
Name Primary: Metric_Codes!$C$50:$C$52
Name quality: Metric_Codes!$C$91:$C$95
Name Recovery_Insurance: Metric_Codes!$C$99:$C$103
Name resource_source: Metric_Codes!$C$34:$C$38
Name resource_speed: Metric_Codes!$C$39:$C$44
Name Scale: Metric_Codes!$C$8:$C$10
Name severity: Metric_Codes!$C$29:$C$33
Name speed: Metric_Codes!$C$82:$C$90

Sheet Data_030520
A1: CS ID | B1: Disaster Name | C1: Country | D1: ISO | E1: Disaster Type | F1: Disaster Subtype | G1: Type | H1: Year | I1: Magnitude | J1: Hazard Magnitude Normalised | K1: Locus | L1: Scale | M1: Population | N1: Economy Type | O1: Economy 2 | P1: Economic Freedom | Q1: Income Group | R1: Economic Growth cat | S1: GDP Growth | T1: GDP per Capita | U1: GNI per Capita | V1: IHDI Value | W1: Gini Coefficient | X1: Corrupt. Index | Y1: Non-Life Insurance Penetration | Z1: Damage Severity | AA1: Economic Loss | AB1: Fatalities | AC1: Displaced | AD1: Affected Population | AE1: Proportion Population Affected | AF1: Self vs external finance | AG1: Government aid | AH1: Non-Governmental aid | AI1: Insured loss | AJ1: Speed of funding | AK1: Adequacy funding | AL1: Role of Insurance | AM1: Resourcing - Confidence | AN1: State of Democracy | AO1: Disaster Management Authority | AP1: Preparedness | AQ1: Public Participation | AR1: Decision Making | AS1: Quality | AT1: Experience | AU1: Economy - Speed | AV1: EconomySpeed - Months | AW1: Economy - Quality | AX1: Economy - Quality Coded | AY1: Economy - Confidence | AZ1: Society - Speed | BA1: SocietySpeed - Months | BB1: Society - Amenity | BC1: Society - Amenity Coded | BD1: Society - Safety | BE1: Society - Safety Coded | BF1: Society total | BG1: Society - Confidence | BH1: Insurance Contribution to Recovery Outcome | BI1: Sources | BJ1: Comments
A2: 1 | B2: 2004 Bangladesh Floods | C2: Bangladesh | D2: BGD | E2: Flood | F2: Riverine Flood | G2: Climate | H2: 2004 | I2: 21,420 km2 | J2: Catastrophic damage | K2: NE & cntrl BGD | L2: Regional | M2: 141307489 | O2: Mixed | P2: 55.6 | Q2: Lower middle | R2: Growing | S2: 0.052395329 | T2: 460.758 | U2: 1650 | V2: 0.462 | W2: 32.4 | X2: 26 | Y2: 0.001588108 | Z2: 60-80% | AA2: 2200000 | AB2: 730 | AC2: 38000 | AD2: 36000000 | AE2: 0.25476357 | AF2: Mostly external | AG2: 60000000 | AH2: 209000000 | AJ2: >12 Months | AK2: Totally insufficient | AL2: Miniimal | AM2: High | AN2: Hybrid regime | AO2: Central gov. | AP2: Unprepared | AQ2: Inadequate | AR2: Limited scientific basis | AS2: Poor | AT2: Frequent | AU2: 6-11 Months | AV2: 9 | AW2: Worse | AX2: =VLOOKUP(AW2,Metric_Codes!$C$91:$D$95,2,FALSE) -> 2 | AY2: Medium | AZ2: 6-11 Months | BA2: 9 | BB2: Same | BC2: =VLOOKUP(BB2,Metric_Codes!$C$91:$D$95,2,FALSE) -> 3 | BD2: Improved | BE2: =VLOOKUP(BD2,Metric_Codes!$C$91:$D$95,2,FALSE) -> 4 | BF2: =(BC2+BE2)/2 -> 3.5 | BG2: Medium | BH2: Negligible | BI2: 96 | BJ2: The floods exacerbated the underlying problems of poverty, unemployment, food insecurity, fresh water supply, health and communication problems. The lack of development in the private insurance markets in Bangladesh has impeded speedy recovery of large industries after floods. Consequently, the central government is responsible for a major share of post-disaster the costs of immediate relief.
A3: 2 | B3: 2012 Hurricane Sandy | C3: United States | D3: USA | E3: Storm | F3: Extratropical Cyclone | G3: Climate | H3: 2012 | I3: CAT 3 | J3: Severe damage | K3: New York/New Jersey | L3: Regional | M3: 313993272 | N3: A: Service-Dominated Economy (more than 75% of economy based on services) | O3: Service-Oriented | P3: 76.8 | Q3: High | R3: Growing | S3: 0.022240309 | T3: 51450.959 | U3: 52850 | V3: 0.797 | W3: 41 | X3: 71 | Y3: 0.04345404 | Z3: 60-80% | AA3: 50000000 | AB3: 54 | AC3: 776000 | AD3: 8000000 | AE3: 0.025478253 | AF3: Mostly external | AG3: 51000000 | AI3: 22800000 | AJ3: >12 Months | AK3: Sufficient | AL3: Major | AM3: High | AN3: Full democracy | AO3: Specialised gov. agency | AP3: Somewhat prepared | AQ3: Adequate | AR3: Established scientific basis | AS3: Good | AT3: Frequent | AU3: <6 Months | AV3: 3 | AW3: Same | AX3: =VLOOKUP(AW3,Metric_Codes!$C$91:$D$95,2,FALSE) -> 3 | AY3: Medium | AZ3: 3-5 Years | BA3: 36 | BB3: Improved | BC3: =VLOOKUP(BB3,Metric_Codes!$C$91:$D$95,2,FALSE) -> 4 | BD3: Improved | BE3: =VLOOKUP(BD3,Metric_Codes!$C$91:$D$95,2,FALSE) -> 4 | BF3: =(BC3+BE3)/2 -> 4 | BG3: Medium | BH3: Crucial | BI3: 69 | BJ3: Sandy the US insurance industry’s second costliest natural disaster. High-value, commercial properties, public infrastructure, and business losses comprised a large proportion of the insured total, while the federal National Flood Insurance Program (NFIP)
A4: 3 | B4: 2005 Hurricane Katrina | C4: United States | D4: USA | E4: Storm | F4: Tropical Cyclone | G4: Climate | H4: 2005 | I4: CAT 5 | J4: Extremely catastrophic damage | K4: New Orleans | L4: Regional | M4: 295516599 | N4: A: Service-Dominated Economy (more than 75% of economy based on services) | O4: Service-Oriented | P4: 76.8 | Q4: High | R4: Growing | S4: 0.033452161 | T4: 44307.921 | U4: 44740 | V4: 0.797 | W4: 40.5 | X4: 71 | Y4: 0.04663638 | Z4: 60-80% | AA4: 125000000 | AB4: 1836 | AC4: 1500000 | AD4: 500000 | AE4: 0.0016919523 | AF4: Mostly external | AG4: 70000000 | AH4: 854000 | AI4: 60000000 | AJ4: >12 Months | AK4: Insufficient | AL4: Major | AM4: High | AN4: Full democracy | AO4: Specialised gov. agency | AP4: Unprepared | AQ4: Inadequate | AR4: Established scientific basis | AS4: Poor | AT4: Frequent | AU4: 3-5 Years | AV4: 48 | AW4: Worse | AX4: =VLOOKUP(AW4,Metric_Codes!$C$91:$D$95,2,FALSE) -> 2 | AY4: Medium | AZ4: 3-5 Years | BA4: 60 | BB4: Worse | BC4: =VLOOKUP(BB4,Metric_Codes!$C$91:$D$95,2,FALSE) -> 2 | BD4: Improved | BE4: =VLOOKUP(BD4,Metric_Codes!$C$91:$D$95,2,FALSE) -> 4 | BF4: =(BC4+BE4)/2 -> 3 | BG4: Medium | BH4: Important | BI4: 22 | BJ4: The hurricane trio had a wide-range of effects on the energy sector, housing, infrastructure, construction and, travel and tourism sectors in the Gulf states of the USA. The storms revealed several fundamental flaws in the management of hurricanes characterized by inept disaster response and inefficiencies in administration of aid after Katrina.
A5: 4 | B5: 2014 India(-Pakistan) floods | C5: India | D5: IND | E5: Flood | F5: Riverine Flood | G5: Climate | H5: 2014 | I5: CAT 4 | J5: Catastrophic damage | K5: Jammu & Kashmir | L5: Regional | M5: 1293859290 | N5: C: Service with Industry (service 50-67% and Industry >25%) | O5: Service-Oriented | P5: 55.2 | Q5: Lower middle | R5: Growing | S5: 0.074102276 | T5: 1574.004 | U5: 5610 | V5: 0.468 | W5: 35.1 | X5: 41 | Y5: 0.006868531 | Z5: 60-80% | AA5: 7000000 | AB5: 53 | AC5: 1300000 | AD5: 920000 | AE5: 0.00071105104 | AF5: Mostly self-funded | AI5: 530000 | AJ5: <6 Months | AK5: Insufficient | AL5: Miniimal | AM5: High | AN5: Full democracy | AO5: Central gov. | AP5: Unprepared | AQ5: Inadequate | AR5: Limited scientific basis | AS5: Mediocre | AT5: Frequent | AU5: <6 Months | AV5: 3 | AW5: Worse | AX5: =VLOOKUP(AW5,Metric_Codes!$C$91:$D$95,2,FALSE) -> 2 | AY5: Medium | AZ5: 6-11 Months | BA5: 9 | BB5: Same | BC5: =VLOOKUP(BB5,Metric_Codes!$C$91:$D$95,2,FALSE) -> 3 | BD5: Same | BE5: =VLOOKUP(BD5,Metric_Codes!$C$91:$D$95,2,FALSE) -> 3 | BF5: =(BC5+BE5)/2 -> 3 | BG5: Medium | BH5: Negligible | BI5: 66 | BJ5: Lack of flood prevention measures, early-warning systems and weak recovery planning processes were cited as chief reasons for the disaster impacts. Agriculture and tourism were the worst affected sectors and this had a significant impact on the regional economy. The floods also exposed political fragilities including the failure of the state to provide timely relief.
A6: 5 | B6: 2013 Typhoon Haiyan (Yolanda) | C6: Philippines | D6: PHL | E6: Storm | F6: Tropical Cyclone | G6: Climate | H6: 2013 | I6: CAT 5 | J6: Extremely catastrophic damage | K6: Eastern Visayas: Tacloban City | L6: Regional | M6: 98481032 | N6: C: Service with Industry (service 50-67% and Industry >25%) | O6: Service-Oriented | P6: 63.8 | Q6: Lower middle | R6: Growing | S6: 0.070640243 | T6: 2760.289 | U6: 7930 | V6: 0.574 | W6: 40.1 | X6: 36 | Y6: 0.004640428 | Z6: 60-80% | AA6: 10000000 | AB6: 7354 | AC6: 4000000 | AD6: 16106870 | AE6: 0.16355302 | AF6: Mostly self-funded | AG6: 2100000 | AH6: 865000 | AI6: 700000 | AJ6: <12 Months | AK6: Sufficient | AL6: Moderate | AM6: High | AN6: Flawed democracy | AO6: Specially-formed agency | AP6: Somewhat prepared | AQ6: Adequate | AR6: Limited scientific basis | AS6: Mediocre | AT6: Frequent | AU6: 1-2 Years | AV6: 18 | AW6: Same | AX6: =VLOOKUP(AW6,Metric_Codes!$C$91:$D$95,2,FALSE) -> 3 | AY6: High | AZ6: 3-5 Years | BA6: 36 | BB6: Improved | BC6: =VLOOKUP(BB6,Metric_Codes!$C$91:$D$95,2,FALSE) -> 4 | BD6: Same | BE6: =VLOOKUP(BD6,Metric_Codes!$C$91:$D$95,2,FALSE) -> 3 | BF6: =(BC6+BE6)/2 -> 3.5 | BG6: High | BH6: Small | BI6: 56 | BJ6: Recovery complicated by Bohol earthquake 3 weeks earlier; Survey of 30 experts;
A7: 6 | B7: 2017 Typhoon Damrey (Ramil) | C7: Vietnam | D7: VNM | E7: Storm | F7: Tropical Cyclone | G7: Climate | H7: 2017 | I7: CAT 2 | J7: Moderate damage | K7: Khanh Hoa Province | L7: Regional | M7: 95540800 | N7: F: Industry with Service (Industry and Service both 33-50%) | O7: Industry with Service | P7: 55.3 | Q7: Lower middle | R7: Growing | S7: 0.068122457 | T7: 2343.125 | U7: 6450 | V7: 0.574 | W7: 34.8 | X7: 33 | Y7: 0.008 | Z7: 20-40% | AA7: 1000000 | AB7: 123 | AC7: 36000 | AD7: 4330000 | AE7: 0.045320952 | AF7: Mostly self-funded | AG7: 13000000 | AJ7: <6 Months | AK7: Insufficient | AL7: Miniimal | AM7: High | AN7: Authoritarian | AO7: Central gov. | AP7: Well prepared | AQ7: Adequate | AR7: Established scientific basis | AS7: Good | AT7: Frequent | AU7: 1-2 Years | AV7: 18 | AW7: Same | AX7: =VLOOKUP(AW7,Metric_Codes!$C$91:$D$95,2,FALSE) -> 3 | AY7: High | AZ7: <6 Months | BA7: 3 | BB7: Same | BC7: =VLOOKUP(BB7,Metric_Codes!$C$91:$D$95,2,FALSE) -> 3 | BD7: Improved | BE7: =VLOOKUP(BD7,Metric_Codes!$C$91:$D$95,2,FALSE) -> 4 | BF7: =(BC7+BE7)/2 -> 3.5 | BG7: High | BH7: Negligible | BI7: 71 | BJ7: Govt grants for poorest based on level of damage; Agriculture and fisheries hit hardest and little Govt aid or incentives to recover; Country experiencing rapid economic growth
A8: 7 | B8: 2013 European floods (Germany) | C8: Germany | D8: DEU | E8: Flood | F8: Riverine Flood | G8: Climate | H8: 2013 | I8: Force 12 | J8: Severe damage | K8: N. Germany (Hamburg) | L8: National | M8: 80645605 | N8: B: Service-Oriented Economy (67-75% of economy based on services) | O8: Mixed | P8: 73.5 | Q8: High | R8: Stable | S8: 0.0048958448 | T8: 47262.283 | U8: 46250 | V8: 0.861 | W8: 31.7 | X8: 80 | Y8: 0.03465669 | Z8: 0-20% | AA8: 12900000 | AB8: 4 | AD8: 1000000 | AE8: 0.012399932 | AF8: Mostly external | AG8: 8000000 | AH8: 0 | AI8: 700000 | AJ8: <12 Months | AK8: Sufficient | AL8: Major | AM8: High | AN8: Full democracy | AO8: Specialised gov. agency | AP8: Well prepared | AQ8: Adequate | AR8: Established scientific basis | AS8: Very good | AT8: Occasional | AU8: <6 Months | AV8: 3 | AW8: Same | AX8: =VLOOKUP(AW8,Metric_Codes!$C$91:$D$95,2,FALSE) -> 3 | AY8: High | AZ8: <1 Month | BA8: 1 | BB8: Same | BC8: =VLOOKUP(BB8,Metric_Codes!$C$91:$D$95,2,FALSE) -> 3 | BD8: Improved | BE8: =VLOOKUP(BD8,Metric_Codes!$C$91:$D$95,2,FALSE) -> 4 | BF8: =(BC8+BE8)/2 -> 3.5 | BG8: High | BH8: Important | BI8: 39 | BJ8: Previous major floods in 2002 and improvements in flood protection and management meant damage less in some places; significant changes in policy since and moves to private insurance rather than State as main funder
A9: 8 | B9: 2007 UK floods | C9: United Kingdom | D9: GBR | E9: Flood | F9: Riverine Flood | G9: Climate | H9: 2007 | I9: Force 13 | J9: Severe damage | K9: S & cntrl British Isles | L9: National | M9: 61322463 | N9: A: Service-Dominated Economy (more than 75% of economy based on services) | O9: Service-Oriented | P9: 78.9 | Q9: High | R9: Growing | S9: 0.023567082 | T9: 50134.316 | U9: 35540 | V9: 0.835 | W9: 33.2 | X9: 80 | Y9: 0.02840852 | Z9: 0-20% | AA9: 4000000 | AB9: 13 | AC9: 30000 | AD9: 1000000 | AE9: 0.016307238 | AF9: Mostly external | AH9: 0 | AI9: 670000 | AJ9: <12 Months | AK9: Sufficient | AL9: Major | AM9: High | AN9: Full democracy | AO9: Specialised gov. agency | AP9: Well prepared | AQ9: Adequate | AR9: Established scientific basis | AS9: Very good | AT9: Occasional | AU9: 6-11 Months | AV9: 9 | AW9: Same | AX9: =VLOOKUP(AW9,Metric_Codes!$C$91:$D$95,2,FALSE) -> 3 | AY9: High | AZ9: 1-2 Years | BA9: 12 | BB9: Same | BC9: =VLOOKUP(BB9,Metric_Codes!$C$91:$D$95,2,FALSE) -> 3 | BD9: Improved | BE9: =VLOOKUP(BD9,Metric_Codes!$C$91:$D$95,2,FALSE) -> 4 | BF9: =(BC9+BE9)/2 -> 3.5 | BG9: High | BH9: Crucial | BI9: 92 | BJ9: Kick started major reviews by Pitt and Bonfield plus significant investment in flood protection and changes in policy; private insurance funded household and business recovery
A10: 9 | B10: 2004 Typhoon Tokage (Siony) | C10: Japan | D10: JPN | E10: Storm | F10: Tropical Cyclone | G10: Climate | H10: 2004 | I10: CAT 4 | J10: Catastrophic damage | K10: Kyushu Island | L10: Regional | M10: 127761000 | N10: B: Service-Oriented Economy (67-75% of economy based on services) | O10: Service-Oriented | P10: 72.1 | Q10: High | R10: Growing | S10: 0.022046879 | T10: 37688.722 | U10: 30930 | V10: 0.876 | W10: 32.1 | X10: 73 | Y10: 0.02224048 | Z10: 20-40% | AA10: 2300000 | AB10: 89 | AC10: 21000 | AD10: 84792 | AE10: 0.00066367671 | AF10: Mostly external | AI10: 1100000 | AJ10: <12 Months | AK10: Sufficient | AL10: Moderate | AM10: Medium | AN10: Full democracy | AO10: Specialised gov. agency | AP10: Well prepared | AQ10: Adequate | AR10: Established scientific basis | AS10: Very good | AT10: Frequent | AU10: <6 Months | AV10: 3 | AW10: Same | AX10: =VLOOKUP(AW10,Metric_Codes!$C$91:$D$95,2,FALSE) -> 3 | AY10: Low | AZ10: 1-2 Years | BA10: 12 | BB10: Same | BC10: =VLOOKUP(BB10,Metric_Codes!$C$91:$D$95,2,FALSE) -> 3 | BD10: Same | BE10: =VLOOKUP(BD10,Metric_Codes!$C$91:$D$95,2,FALSE) -> 3 | BF10: =(BC10+BE10)/2 -> 3 | BG10: Low | BH10: Small | BI10: 1 | BJ10: Affected entire S part of Japan; 1 of 5 major typhoons in 2004 causing widesread flooding
A11: 10 | B11: 2010 China Floods | C11: China | D11: CHN | E11: Flood | F11: Riverine Flood | G11: Climate | H11: 2010 | I11: Flood 4 | J11: Catastrophic damage | K11: 28 mainland Provinces | L11: National | M11: 1337705000 | N11: C: Service with Industry (service 50-67% and Industry >25%) | O11: Mixed | P11: 67.3 | Q11: Upper middle | R11: Growing | S11: 0.1063614 | T11: 4560.513 | U11: 9290 | V11: 0.643 | W11: 42.2 | X11: 39 | Y11: 0.01192495 | Z11: 60-80% | AA11: 18171000 | AB11: 1691 | AC11: 15200000 | AD11: 134000000 | AE11: 0.10017156 | AF11: Mostly self-funded | AI11: 596000 | AJ11: <12 Months | AK11: Insufficient | AL11: Miniimal | AM11: High | AN11: Authoritarian | AO11: Central gov. | AP11: Somewhat prepared | AQ11: Inadequate | AR11: Established scientific basis | AS11: Good | AT11: Major | AU11: 1-2 Years | AV11: 18 | AW11: Same | AX11: =VLOOKUP(AW11,Metric_Codes!$C$91:$D$95,2,FALSE) -> 3 | AY11: Low | AZ11: 1-2 Years | BA11: 18 | BB11: Same | BC11: =VLOOKUP(BB11,Metric_Codes!$C$91:$D$95,2,FALSE) -> 3 | BD11: Improved | BE11: =VLOOKUP(BD11,Metric_Codes!$C$91:$D$95,2,FALSE) -> 4 | BF11: =(BC11+BE11)/2 -> 3.5 | BG11: Low | BH11: Negligible | BI11: 5 | BJ11: Severe monsoon season; environmental concerns about over development along Yangtze; most caualties from mudslides; little impact on agricultual production
A12: 11 | B12: 1998 Hurricane Mitch | C12: Honduras | D12: HND | E12: Storm | F12: Tropical Cyclone | G12: Climate | H12: 1998 | I12: CAT 5 | J12: Extremely catastrophic damage | K12: Nationwide | L12: National | M12: 6192026 | N12: D: Service with Industrial/Ag Mix (Service >50%, Industry 15-25% and Ag 15-30%) | O12: Mixed | P12: 60.2 | Q12: Lower middle | R12: Growing | S12: 0.036 | T12: 1028.2 | U12: 2430 | V12: 0.459 | W12: 50.5 | X12: 29 | Y12: 0.006 | Z12: 80-100% | AA12: 3800000 | AB12: 22658 | AC12: 441150 | AD12: 868228 | AE12: 0.14021711 | AF12: Mostly external | AH12: 2800000 | AI12: 150000 | AJ12: >12 Months | AK12: Insufficient | AL12: Moderate | AM12: High | AN12: Hybrid regime | AO12: Central gov. | AP12: Completely unprepared | AQ12: Inadequate | AR12: Limited scientific basis | AS12: Poor | AT12: Frequent | AU12: 3-5 Years | AV12: 48 | AW12: Much worse | AX12: =VLOOKUP(AW12,Metric_Codes!$C$91:$D$95,2,FALSE) -> 1 | AY12: Medium | AZ12: 3-5 Years | BA12: 60 | BB12: Same | BC12: =VLOOKUP(BB12,Metric_Codes!$C$91:$D$95,2,FALSE) -> 3 | BD12: Same | BE12: =VLOOKUP(BD12,Metric_Codes!$C$91:$D$95,2,FALSE) -> 3 | BF12: =(BC12+BE12)/2 -> 3 | BG12: Medium | BH12: Small | BI12: 10 | BJ12: Huge rainfall and flooding, deforestation;direct and indirect losses 70% GDP; 70% agriculture destroyed; prompted debate about morality of international debt
A13: 12 | B13: 2004 Hurricane Frances | C13: Bahamas, The | D13: BHS | E13: Storm | F13: Tropical Cyclone | G13: Climate | H13: 2004 | I13: CAT 4 | J13: Catastrophic damage | K13: All islands | L13: National | M13: 322526 | O13: Industry-Oriented | P13: 62.9 | Q13: High | R13: Stable | S13: 0.0088283993 | T13: 28076.155 | U13: 21380 | V13: 0.755 | W13: 46 | X13: 65 | Y13: 0.03588563 | Z13: 20-40% | AA13: 1000000 | AB13: 2 | AC13: 2500 | AD13: 8000 | AE13: 0.024804202 | AF13: Mostly self-funded | AI13: 230000 | AJ13: >12 Months | AK13: Insufficient | AL13: Moderate | AM13: High | AN13: Flawed democracy | AO13: Central gov. | AP13: Unprepared | AQ13: Inadequate | AR13: Limited scientific basis | AS13: Poor | AT13: Occasional | AU13: 6-11 Months | AV13: 9 | AW13: Same | AX13: =VLOOKUP(AW13,Metric_Codes!$C$91:$D$95,2,FALSE) -> 3 | AY13: Low | AZ13: 1-2 Years | BA13: 18 | BB13: Same | BC13: =VLOOKUP(BB13,Metric_Codes!$C$91:$D$95,2,FALSE) -> 3 | BD13: Same | BE13: =VLOOKUP(BD13,Metric_Codes!$C$91:$D$95,2,FALSE) -> 3 | BF13: =(BC13+BE13)/2 -> 3 | BG13: Low | BH13: Small | BI13: 12 | BJ13: Also hit Florida and USA where it caused most economic damage (US 9 billion) and fatalities;
A14: 13 | B14: 2004 Hurricane Ivan | C14: Jamaica | D14: JAM | E14: Storm | F14: Tropical Cyclone | G14: Climate | H14: 2004 | I14: CAT 5 | J14: Extremely catastrophic damage | K14: Nationwide | L14: National | M14: 2728777 | O14: Service-Oriented | P14: 68.6 | Q14: Upper middle | R14: Stable | S14: 0.013237251 | T14: 3719.974 | U14: 6820 | V14: 0.608 | W14: 45.5 | X14: 44 | Y14: 0.0302802 | Z14: 60-80% | AA14: 595000 | AB14: 15 | AC14: 18000 | AD14: 350000 | AE14: 0.12826259 | AF14: Mostly self-funded | AH14: 40000 | AI14: 200000 | AJ14: >12 Months | AK14: Insufficient | AL14: Moderate | AM14: High | AN14: Flawed democracy | AO14: Specialised gov. agency | AP14: Somewhat prepared | AQ14: Inadequate | AR14: No scientific basis | AS14: Poor | AT14: Frequent | AU14: 6-11 Months | AV14: 9 | AW14: Same | AX14: =VLOOKUP(AW14,Metric_Codes!$C$91:$D$95,2,FALSE) -> 3 | AY14: Medium | AZ14: 1-2 Years | BA14: 18 | BB14: Same | BC14: =VLOOKUP(BB14,Metric_Codes!$C$91:$D$95,2,FALSE) -> 3 | BD14: Same | BE14: =VLOOKUP(BD14,Metric_Codes!$C$91:$D$95,2,FALSE) -> 3 | BF14: =(BC14+BE14)/2 -> 3 | BG14: Medium | BH14: Small | BI14: 44 | BJ14: Creation of Office of National Reconstruction (ONR) outside the legally established agencies unhelpful; Parish Disaster Committees, were expected to have, but lacked, the capacity for assessment and response; big hit for agricultural production
A15: 14 | B15: 1994 Northridge earthquake | C15: United States | D15: USA | E15: Earthquake | F15: Earthquake & Tsunami | G15: Geophysical | H15: 1994 | I15: 6.7 Mw | J15: Severe damage | K15: Northridge | L15: Regional | M15: 263126000 | N15: A: Service-Dominated Economy (more than 75% of economy based on services) | O15: Service-Oriented | P15: 76.8 | Q15: High | R15: Growing | S15: 0.04 | T15: 27776.6 | U15: 52308 | V15: 0.755 | W15: 41 | X15: 71 | Y15: 0.04813937 | Z15: 60-80% | AA15: 30000000 | AB15: 72 | AC15: 114000 | AD15: 3800000 | AE15: 0.01444175 | AF15: Mostly external | AG15: 8600000 | AI15: 13900000 | AJ15: <12 Months | AK15: Sufficient | AL15: Major | AM15: High | AN15: Full democracy | AO15: Central gov. | AP15: Somewhat prepared | AQ15: Adequate | AR15: Established scientific basis | AS15: Good | AT15: Infrequent | AU15: 1-2 Years | AV15: 18 | AW15: Same | AX15: =VLOOKUP(AW15,Metric_Codes!$C$91:$D$95,2,FALSE) -> 3 | AY15: High | AZ15: 1-2 Years | BA15: 18 | BB15: Same | BC15: =VLOOKUP(BB15,Metric_Codes!$C$91:$D$95,2,FALSE) -> 3 | BD15: Same | BE15: =VLOOKUP(BD15,Metric_Codes!$C$91:$D$95,2,FALSE) -> 3 | BF15: =(BC15+BE15)/2 -> 3 | BG15: High | BH15: Important | BI15: 37 | BJ15: Private household insurnace reduced recovery time by 1 year over familes recieving governments grants
A16: 15 | B16: 2003 Bam earthquake | C16: Iran, Islamic Rep. | D16: IRN | E16: Earthquake | F16: Earthquake | G16: Geophysical | H16: 2003 | I16: 6.6 Mw | J16: Severe damage | K16: Bam | L16: Regional | M16: 68812713 | N16: F: Industry with Service (Industry and Service both 33-50%) | O16: Mixed | P16: 51.1 | Q16: Upper middle | R16: Growing | S16: 0.07 | T16: 2231.3 | U16: 13451 | V16: 0.498 | W16: 38 | X16: 28 | Y16: 0.009347397 | Z16: 80-100% | AA16: 500000 | AB16: 30000 | AC16: 75600 | AD16: 100000 | AE16: 0.0014532198 | AF16: Self-funded | AG16: 410000 | AJ16: >24 Months | AK16: Totally insufficient | AL16: Miniimal | AM16: High | AN16: Authoritarian | AO16: Central gov. | AP16: Unprepared | AQ16: Inadequate | AR16: Limited scientific basis | AS16: Very poor | AT16: Frequent | AU16: 11-20 Years | AV16: 180 | AW16: Much worse | AX16: =VLOOKUP(AW16,Metric_Codes!$C$91:$D$95,2,FALSE) -> 1 | AY16: Medium | AZ16: 6-10 Years | BA16: 120 | BB16: Worse | BC16: =VLOOKUP(BB16,Metric_Codes!$C$91:$D$95,2,FALSE) -> 2 | BD16: Improved | BE16: =VLOOKUP(BD16,Metric_Codes!$C$91:$D$95,2,FALSE) -> 4 | BF16: =(BC16+BE16)/2 -> 3 | BG16: High | BH16: Negligible | BI16: 86 | BJ16: Collapse of adobe structures caused high casualties; dates producing area; never fully recovered; many housing plots still vacant because owners
A17: 16 | B17: 2004 Indian Ocean earthquake and tsunami | C17: Thailand | D17: THA | E17: Earthquake & Tsunami | F17: Earthquake | G17: Geophysical | H17: 2004 | I17: 9.1 Mw | J17: Extremely catastrophic damage | K17: Indian Ocean | L17: Regional | M17: 65002231 | N17: C: Service with Industry (service 50-67% and Industry >25%) | O17: Industry with Service | P17: 68.3 | Q17: Upper middle | R17: Growing | S17: 0.06 | T17: 2659.8 | U17: 13364 | V17: 0.573 | W17: 39 | X17: 36 | Y17: 0.01253271 | Z17: 80-100% | AA17: 30000000 | AB17: 9311 | AC17: 1800000 | AD17: 2133784 | AE17: 0.032826319 | AF17: Equal | AG17: 1700000 | AI17: 2700000 | AJ17: <12 Months | AK17: Surplus | AL17: Miniimal | AM17: Medium | AN17: Hybrid regime | AO17: Central gov. | AP17: Unprepared | AQ17: Inadequate | AR17: Limited scientific basis | AS17: Poor | AT17: Infrequent | AU17: 3-5 Years | AV17: 36 | AW17: Improved | AX17: =VLOOKUP(AW17,Metric_Codes!$C$91:$D$95,2,FALSE) -> 4 | AY17: High | AZ17: 3-5 Years | BA17: 36 | BB17: Worse | BC17: =VLOOKUP(BB17,Metric_Codes!$C$91:$D$95,2,FALSE) -> 2 | BD17: Same | BE17: =VLOOKUP(BD17,Metric_Codes!$C$91:$D$95,2,FALSE) -> 3 | BF17: =(BC17+BE17)/2 -> 2.5 | BG17: High | BH17: Negligible | BI17: 7 | BJ17: Huge disaster; Massive international aid slowed recovery in some places like Thailand; influx of new people kick started economy
A18: 17 | B18: 2005 Kashmir earthquake | C18: Pakistan | D18: PAK | E18: Earthquake | F18: Earthquake | G18: Geophysical | H18: 2005 | I18: 7.6 Mw | J18: Catastrophic damage | K18: Kashmir NW Frontier | L18: Regional | M18: 153909667 | N18: C: Service with Industry (service 50-67% and Industry >25%) | O18: Industry with Service | P18: 61 | Q18: Lower middle | R18: Growing | S18: 0.09 | T18: 711.5 | U18: 4652 | V18: 0.375 | W18: 30 | X18: 33 | Y18: 0.003924284 | Z18: 60-80% | AA18: 5200000 | AB18: 87000 | AC18: 3200000 | AD18: 10143700 | AE18: 0.065906841 | AF18: Mostly self-funded | AG18: 483000 | AI18: 5000 | AJ18: >12 Months | AK18: Insufficient | AL18: Miniimal | AM18: High | AN18: Hybrid regime | AO18: Specially-formed agency | AP18: Unprepared | AQ18: Inadequate | AR18: No scientific basis | AS18: Poor | AT18: Frequent | AU18: 3-5 Years | AV18: 48 | AW18: Worse | AX18: =VLOOKUP(AW18,Metric_Codes!$C$91:$D$95,2,FALSE) -> 2 | AY18: Medium | AZ18: 6-10 Years | BA18: 96 | BB18: Worse | BC18: =VLOOKUP(BB18,Metric_Codes!$C$91:$D$95,2,FALSE) -> 2 | BD18: Same | BE18: =VLOOKUP(BD18,Metric_Codes!$C$91:$D$95,2,FALSE) -> 3 | BF18: =(BC18+BE18)/2 -> 2.5 | BG18: High | BH18: Negligible | BI18: 375 | BJ18: High death toll, especially of school childre, caused by poor construction; army suffered high casualities which affected command and control in a military state; complicated by Kashmir conflict; plans for relocate Balakot thwarted; Speciall agency EERA; hopes of building back better unrealised
A19: 18 | B19: 2008 Sichuan (Wenchuan) earthquake | C19: China | D19: CHN | E19: Earthquake | F19: Earthquake & Tsunami | G19: Geophysical | H19: 2008 | I19: 7.9 Mw | J19: Catastrophic damage | K19: Wenchuan | L19: Regional | M19: 1324655000 | N19: C: Service with Industry (service 50-67% and Industry >25%) | O19: Mixed | P19: 67.3 | Q19: Upper middle | R19: Growing | S19: 0.1 | T19: 3471.2 | U19: 11477 | V19: 0.643 | W19: 37 | X19: 39 | Y19: 0.009855344 | Z19: 60-80% | AA19: 130000000 | AB19: 87587 | AC19: 5000000 | AD19: 15000000 | AE19: 0.011323703 | AF19: Mostly external | AG19: 10000000 | AI19: 366000 | AJ19: <6 Months | AK19: Sufficient | AL19: Miniimal | AM19: High | AN19: Authoritarian | AO19: Central gov. | AP19: Unprepared | AQ19: Inadequate | AR19: Limited scientific basis | AS19: Poor | AT19: Frequent | AU19: 1-2 Years | AV19: 18 | AW19: Improved | AX19: =VLOOKUP(AW19,Metric_Codes!$C$91:$D$95,2,FALSE) -> 4 | AY19: Medium | AZ19: 1-2 Years | BA19: 12 | BB19: Worse | BC19: =VLOOKUP(BB19,Metric_Codes!$C$91:$D$95,2,FALSE) -> 2 | BD19: Improved | BE19: =VLOOKUP(BD19,Metric_Codes!$C$91:$D$95,2,FALSE) -> 4 | BF19: =(BC19+BE19)/2 -> 3 | BG19: High | BH19: Negligible | BI19: 36 | BJ19: Rapid recovery;massive aid effort from unaffected cities in south; issues that rapid rebuilding insensitive to special environmental and cultural character of region;
A20: 19 | B20: 2009 L'Aquila earthquake | C20: Italy | D20: ITA | E20: Earthquake | F20: Earthquake | G20: Geophysical | H20: 2009 | I20: 6.2 Mw | J20: Severe damage | K20: L'Aquila | L20: Regional | M20: 59095365 | N20: A: Service-Dominated Economy (more than 75% of economy based on services) | O20: Industry-Oriented | P20: 62.2 | Q20: High | R20: Contracting | S20: -0.06 | T20: 36976.8 | U20: 32669 | V20: 0.768 | W20: 35 | X20: 52 | Y20: 0.02396951 | Z20: 60-80% | AA20: 11600000 | AB20: 308 | AC20: 65000 | AD20: 72000 | AE20: 0.0012183697 | AF20: Equal | AG20: 484000 | AI20: 200000 | AJ20: >12 Months | AK20: Insufficient | AL20: Moderate | AM20: High | AN20: Flawed democracy | AO20: Central gov. | AP20: Somewhat prepared | AQ20: Inadequate | AR20: No scientific basis | AS20: Very poor | AT20: Frequent | AU20: 6-10 Years | AV20: 96 | AW20: Much worse | AX20: =VLOOKUP(AW20,Metric_Codes!$C$91:$D$95,2,FALSE) -> 1 | AY20: High | AZ20: 6-10 Years | BA20: 120 | BB20: Much worse | BC20: =VLOOKUP(BB20,Metric_Codes!$C$91:$D$95,2,FALSE) -> 1 | BD20: Improved | BE20: =VLOOKUP(BD20,Metric_Codes!$C$91:$D$95,2,FALSE) -> 4 | BF20: =(BC20+BE20)/2 -> 2.5 | BG20: High | BH20: Small | BI20: 40 | BJ20: Stagnant regional economy; lack of cooperation between various local authorities - municiplaity, province and region; inappropriate intervention by Berlusconi central govewrnment in relocating displaced to new distant settlement; ancient city centre 'moth-balled'; heroic effort by fire brigade to scaffold and preserve historic buildings
A21: 20 | B21: 2010 Maule earthquake | C21: Chile | D21: CHL | E21: Earthquake & Tsunami | F21: Earthquake | G21: Geophysical | H21: 2010 | I21: 8.8 Mw | J21: Extremely catastrophic damage | K21: Concepción | L21: Regional | M21: 16993354 | N21: B: Service-Oriented Economy (67-75% of economy based on services) | O21: Service-Oriented | P21: 58.4 | Q21: High | R21: Growing | S21: 0.06 | T21: 12860.2 | U21: 20804 | V21: 0.661 | W21: 51 | X21: 67 | Y21: 0.01481713 | Z21: 40-60% | AA21: 30000000 | AB21: 547 | AC21: 800000 | AD21: 5540000 | AE21: 0.3260098 | AF21: Equal | AG21: 110000 | AI21: 5500000 | AJ21: >12 Months | AK21: Sufficient | AL21: Moderate | AM21: Medium | AN21: Flawed democracy | AO21: Specially-formed agency | AP21: Well prepared | AQ21: Extensive | AR21: Established scientific basis | AS21: Very good | AT21: Frequent | AU21: 3-5 Years | AV21: 36 | AW21: Improved | AX21: =VLOOKUP(AW21,Metric_Codes!$C$91:$D$95,2,FALSE) -> 4 | AY21: High | AZ21: 3-5 Years | BA21: 36 | BB21: Improved | BC21: =VLOOKUP(BB21,Metric_Codes!$C$91:$D$95,2,FALSE) -> 4 | BD21: Improved | BE21: =VLOOKUP(BD21,Metric_Codes!$C$91:$D$95,2,FALSE) -> 4 | BF21: =(BC21+BE21)/2 -> 4 | BG21: High | BH21: Moderate | BI21: 59 | BJ21: Fast response by central govt to prepare national plan and legislate for funding; delegating implementation to regional government who set up team of archiects and planners to plan and manage reconstruction; exemplorary community involvement; effort to provide temporary accommodation for local businesses;
A22: 21 | B22: 2011 Christchurch earthquake | C22: New Zealand | D22: NZL | E22: Earthquake | F22: Earthquake | G22: Geophysical | H22: 2011 | I22: 6.3 Mw | J22: Severe damage | K22: Christchurch | L22: Regional | M22: 4384000 | N22: A: Service-Dominated Economy (more than 75% of economy based on services) | O22: Service-Oriented | P22: 84.4 | Q22: High | R22: Stable | S22: 0.01 | T22: 38426.6 | U22: 32569 | V22: 0.846 | W22: 33 | X22: 87 | Y22: 0.04931718 | Z22: 40-60% | AA22: 15000000 | AB22: 181 | AC22: 70000 | AD22: 348435 | AE22: 0.079478786 | AF22: Mostly external | AG22: 11400000 | AI22: 12000000 | AJ22: <12 Months | AK22: Sufficient | AL22: Major | AM22: High | AN22: Full democracy | AO22: Specially-formed agency | AP22: Well prepared | AQ22: Adequate | AR22: Established scientific basis | AS22: Mediocre | AT22: Infrequent | AU22: 3-5 Years | AV22: 48 | AW22: Same | AX22: =VLOOKUP(AW22,Metric_Codes!$C$91:$D$95,2,FALSE) -> 3 | AY22: High | AZ22: 3-5 Years | BA22: 60 | BB22: Same | BC22: =VLOOKUP(BB22,Metric_Codes!$C$91:$D$95,2,FALSE) -> 3 | BD22: Improved | BE22: =VLOOKUP(BD22,Metric_Codes!$C$91:$D$95,2,FALSE) -> 4 | BF22: =(BC22+BE22)/2 -> 3.5 | BG22: High | BH22: Crucial | BI22: 77 | BJ22: Severe liquifaction in Avon valley has meant large residential area red zones and then abandoned; city centre decimated; businesses relocated to 6 periferal commercial centres; v high level of insurance; minister advocated demolition of heritage masonry buildings; many after shocks created intense complexity to resolve claims
A23: 22 | B23: 2011 Tōhoku earthquake and tsunami | C23: Japan | D23: JPN | E23: Earthquake & Tsunami | F23: Earthquake | G23: Geophysical | H23: 2011 | I23: 9.0 Mw | J23: Extremely catastrophic damage | K23: Tohoku | L23: Regional | M23: 127833000 | N23: B: Service-Oriented Economy (67-75% of economy based on services) | O23: Service-Oriented | P23: 72.1 | Q23: High | R23: Contracting | S23: -0.05 | T23: 48168 | U23: 36747 | V23: 0.779 | W23: 32 | X23: 73 | Y23: 0.02186681 | Z23: 60-80% | AA23: 210000000 | AB23: 20350 | AC23: 5150000 | AD23: 9630000 | AE23: 0.075332661 | AF23: Mostly external | AG23: 266000000 | AI23: 35000000 | AJ23: <12 Months | AK23: Sufficient | AL23: Major | AM23: High | AN23: Full democracy | AO23: Specialised gov. agency | AP23: Somewhat prepared | AQ23: Adequate | AR23: Established scientific basis | AS23: Mediocre | AT23: Frequent | AU23: 6-10 Years | AV23: 96 | AW23: Worse | AX23: =VLOOKUP(AW23,Metric_Codes!$C$91:$D$95,2,FALSE) -> 2 | AY23: High | AZ23: 6-10 Years | BA23: 108 | BB23: Worse | BC23: =VLOOKUP(BB23,Metric_Codes!$C$91:$D$95,2,FALSE) -> 2 | BD23: Much improved | BE23: =VLOOKUP(BD23,Metric_Codes!$C$91:$D$95,2,FALSE) -> 5 | BF23: =(BC23+BE23)/2 -> 3.5 | BG23: High | BH23: Important | BI23: 92 | BJ23: Severe shock to highly prepared country that imagined it was protected; high death toll in Sendai plain area; Iwate province already in demographic and economic decline; plans to relocate people from small ports deemed as unviable and consolidation of settlements thwarted by requirment to consult and reach concensus withelderly men
A24: 23 | B24: 2011 Van earthquake | C24: Turkey | D24: TUR | E24: Earthquake | F24: Earthquake & Tsunami | G24: Geophysical | H24: 2011 | I24: 7.1 Mw | J24: Catastrophic damage | K24: Van | L24: Regional | M24: 73409455 | N24: B: Service-Oriented Economy (67-75% of economy based on services) | O24: Industry with Service | P24: 64.6 | Q24: Upper middle | R24: Growing | S24: 0.08 | T24: 11340.8 | U24: 18391 | V24: 0.639 | W24: 39 | X24: 41 | Y24: 0.01091015 | Z24: 0-20% | AA24: 1500000 | AB24: 601 | AC24: 180000 | AD24: 1000000 | AE24: 0.013622223 | AF24: Mostly self-funded | AG24: 2000000 | AI24: 200000 | AJ24: >24 Months | AK24: Sufficient | AL24: Miniimal | AM24: High | AN24: Hybrid regime | AO24: Specialised gov. agency | AP24: Well prepared | AQ24: Inadequate | AR24: Established scientific basis | AS24: Mediocre | AT24: Frequent | AU24: 3-5 Years | AV24: 48 | AW24: Same | AX24: =VLOOKUP(AW24,Metric_Codes!$C$91:$D$95,2,FALSE) -> 3 | AY24: High | AZ24: 1-2 Years | BA24: 18 | BB24: Worse | BC24: =VLOOKUP(BB24,Metric_Codes!$C$91:$D$95,2,FALSE) -> 2 | BD24: Improved | BE24: =VLOOKUP(BD24,Metric_Codes!$C$91:$D$95,2,FALSE) -> 4 | BF24: =(BC24+BE24)/2 -> 3 | BG24: High | BH24: Negligible | BI24: 133 | BJ24: Modertae earthquake in fast east away from main centres of power; Kurdish area; compicated by Kurdish separatist movement; new Toki housing constructed very quickly with no regard for local ways of life or architecture; safety of repair compromised by corruption
A25: 24 | B25: 2015 Gorkha earthquake | C25: Nepal | D25: NPL | E25: Earthquake | F25: Earthquake | G25: Geophysical | H25: 2015 | I25: 7.8 Mw | J25: Catastrophic damage | K25: Gorkha | L25: National | M25: 28656282 | O25: Industry-Oriented | P25: 53.8 | Q25: Low | R25: Growing | S25: 0.0332 | T25: 747.16 | U25: 2500 | V25: 0.427 | W25: 32.8 | X25: 31 | Y25: <0.5% | Z25: 60-80% | AA25: 5174000 | AB25: 8831 | AC25: 81000 | AD25: 5639722 | AE25: 0.19680578 | AF25: Mostly self-funded | AG25: 178000 | AH25: 241000 | AI25: 100000 | AJ25: >12 Months | AK25: Insufficient | AL25: Miniimal | AM25: High | AN25: Hybrid regime | AO25: Specially-formed agency | AP25: Unprepared | AQ25: Inadequate | AR25: No scientific basis | AS25: Poor | AT25: Frequent | AU25: 3-5 Years | AV25: 48 | AW25: Same | AX25: =VLOOKUP(AW25,Metric_Codes!$C$91:$D$95,2,FALSE) -> 3 | AY25: High | AZ25: 6-10 Years | BA25: 84 | BB25: Same | BC25: =VLOOKUP(BB25,Metric_Codes!$C$91:$D$95,2,FALSE) -> 3 | BD25: Same | BE25: =VLOOKUP(BD25,Metric_Codes!$C$91:$D$95,2,FALSE) -> 3 | BF25: =(BC25+BE25)/2 -> 3 | BG25: High | BH25: Negligible | BI25: 61 | BJ25: High death toll from poor constrcution in both rural and urban areas; Earthquake advice to crawl under a table meant that many killed when they ran back indoors rather than staying safe outside; compensation to rebuild hampered by corruption;
A26: 25 | B26: 1995 Great Hanshin (Kobe) earthquake | C26: Japan | D26: JPN | E26: Earthquake | F26: Earthquake | G26: Geophysical | H26: 1995 | I26: 6.9 Mw | J26: Severe damage | K26: Kobe | L26: Regional | M26: 92500572 | N26: B: Service-Oriented Economy (67-75% of economy based on services) | O26: Service-Oriented | P26: 72.1 | Q26: High | R26: Growing | S26: 0.027 | T26: 43440.4 | U26: 23610 | V26: 0.876 | W26: 32.1 | X26: 73 | Y26: 0.02405965 | Z26: 60-80% | AA26: 100000000 | AB26: 5297 | AD26: 541636 | AE26: 0.0058554881 | AF26: Equal | AG26: 8070000 | AH26: 44812000 | AI26: 3000000 | AJ26: <12 Months | AK26: Sufficient | AL26: Moderate | AM26: Medium | AN26: Full democracy | AO26: Central gov. | AP26: Well prepared | AQ26: Inadequate | AR26: Established scientific basis | AS26: Good | AT26: Frequent | AU26: 1-2 Years | AV26: 18 | AW26: Worse | AX26: =VLOOKUP(AW26,Metric_Codes!$C$91:$D$95,2,FALSE) -> 2 | AY26: High | AZ26: 3-5 Years | BA26: 48 | BB26: Improved | BC26: =VLOOKUP(BB26,Metric_Codes!$C$91:$D$95,2,FALSE) -> 4 | BD26: Much improved | BE26: =VLOOKUP(BD26,Metric_Codes!$C$91:$D$95,2,FALSE) -> 5 | BF26: =(BC26+BE26)/2 -> 4.5 | BG26: High | BH26: Small | BI26: 11 | BJ26: High death toll from heavy stone roofs and removal of internal sheer walls;
A27: 26 | B27: 2010 Haiti earthquake | C27: Haiti | D27: HTI | E27: Earthquake & Tsunami | F27: Earthquake & Tsunami | G27: Geophysical | H27: 2010 | I27: 7.0 Mw | J27: Catastrophic damage | K27: Port-au-Prince | L27: Regional | M27: 9999617 | O27: Service-Oriented | P27: 52.7 | Q27: Low | R27: Contracting | S27: -0.055 | T27: 662.3 | U27: 1480 | V27: 0.304 | W27: 41.1 | X27: 20 | Y27: 0.003 | Z27: 80-100% | AA27: 8000000 | AB27: 222570 | AC27: 1500000 | AD27: 3700000 | AE27: 0.37001417 | AF27: Mostly self-funded | AH27: 1600000 | AI27: 150000 | AJ27: <12 Months | AK27: Insufficient | AL27: Miniimal | AM27: High | AN27: Hybrid regime | AO27: Central gov. | AP27: Completely unprepared | AQ27: Extensive | AR27: Limited scientific basis | AS27: Very poor | AT27: Frequent | AU27: 6-10 Years | AV27: 96 | AW27: Same | AX27: =VLOOKUP(AW27,Metric_Codes!$C$91:$D$95,2,FALSE) -> 3 | AY27: Medium | AZ27: 6-10 Years | BA27: 108 | BB27: Same | BC27: =VLOOKUP(BB27,Metric_Codes!$C$91:$D$95,2,FALSE) -> 3 | BD27: Same | BE27: =VLOOKUP(BD27,Metric_Codes!$C$91:$D$95,2,FALSE) -> 3 | BF27: =(BC27+BE27)/2 -> 3 | BG27: Medium | BH27: Negligible | BI27: 18 | BJ27: Massive death toll; chaotic; lack of effective government; lack of datato measure impact, assess need or track recovery. Many NGOs involved in recovery
A28: 27 | B28: 2010 Mentawai earthquake and tsunami | C28: Indonesia | D28: IDN | E28: Earthquake & Tsunami | F28: Earthquake & Tsunami | G28: Geophysical | H28: 2010 | I28: 7.8 Mw | J28: Catastrophic damage | K28: Mentawai | L28: Regional | M28: 242524123 | N28: C: Service with Industry (service 50-67% and Industry >25%) | O28: Mixed | P28: 65.8 | Q28: Lower middle | R28: Growing | S28: 0.062 | T28: 3113.5 | U28: 8040 | V28: 0.563 | W28: 38.1 | X28: 38 | Y28: 0.004087398 | Z28: 40-60% | AA28: 3482 | AB28: 530 | AC28: 20000 | AD28: 11864 | AE28: 4.8918845e-05 | AF28: Mostly self-funded | AH28: 81000 | AJ28: >24 Months | AK28: Insufficient | AL28: Miniimal | AM28: High | AN28: Flawed democracy | AO28: Specialised gov. agency | AP28: Somewhat prepared | AQ28: Inadequate | AR28: Limited scientific basis | AS28: Poor | AT28: Frequent | AU28: 1-2 Years | AV28: 18 | AW28: Same | AX28: =VLOOKUP(AW28,Metric_Codes!$C$91:$D$95,2,FALSE) -> 3 | AY28: Low | AZ28: 3-5 Years | BA28: 36 | BB28: Same | BC28: =VLOOKUP(BB28,Metric_Codes!$C$91:$D$95,2,FALSE) -> 3 | BD28: Improved | BE28: =VLOOKUP(BD28,Metric_Codes!$C$91:$D$95,2,FALSE) -> 4 | BF28: =(BC28+BE28)/2 -> 3.5 | BG28: Medium | BH28: Negligible | BI28: 12 | BJ28: Isolated Christain area in a Muslim country
A29: 28 | B29: 1931 China Floods | C29: China | D29: CHN | E29: Flood | F29: Riverine Flood | G29: Climate | H29: 1931 | I29: 180,000 km2; max water leve 16 m (Wuhan); av. 1.7 m above Shanghai Bund | J29: Extremely catastrophic damage | K29: Anhui, Hubei (esp. Wuhan), Hunan, Jiangsu, Zhejiang, Jiangxi, Henan, Shandong | L29: National | M29: 667070000 | N29: C: Service with Industry (service 50-67% and Industry >25%) | O29: Mixed | P29: 67.3 | Q29: Upper middle | R29: Contracting | S29: -0.2727 | T29: 89.52 | U29: 990 | V29: 0.643 | W29: 38.6 | X29: 39 | Z29: 80-100% | AA29: 1400000 | AB29: 3700000 | AC29: 25000000 | AF29: Mostly self-funded | AJ29: >24 Months | AK29: Totally insufficient | AL29: Miniimal | AM29: High | AN29: Authoritarian | AO29: Central gov. | AP29: Completely unprepared | AQ29: Inadequate | AR29: Established scientific basis | AS29: Very poor | AT29: Frequent | AU29: 11-20 Years | AV29: 180 | AW29: Improved | AX29: =VLOOKUP(AW29,Metric_Codes!$C$91:$D$95,2,FALSE) -> 4 | AY29: Low | AZ29: 11-20 Years | BA29: 180 | BB29: Improved | BC29: =VLOOKUP(BB29,Metric_Codes!$C$91:$D$95,2,FALSE) -> 4 | BD29: Improved | BE29: =VLOOKUP(BD29,Metric_Codes!$C$91:$D$95,2,FALSE) -> 4 | BF29: =(BC29+BE29)/2 -> 4 | BG29: Low | BH29: Negligible | BI29: 5 | BJ29: recovery slowed by japanese invasion, civil war and Communist take-over
A30: 29 | B30: 1937 (Ohio River) Great Flood | C30: United States | D30: USA | E30: Flood | F30: Riverine Flood | G30: Climate | H30: 1937 | I30: Max water Evansville, Indiana (16 m); Cincinnati (24 m); Louisville (17 m); Paducah, Kentucky (18 m) | J30: Catastrophic damage | K30: Ohio | L30: Regional | M30: 180671000 | N30: A: Service-Dominated Economy (more than 75% of economy based on services) | O30: Service-Oriented | P30: 76.8 | Q30: High | R30: Growing | S30: 0.023 | T30: 3007.12 | U30: 23730 | V30: 0.797 | W30: 41.5 | X30: 71 | Z30: 60-80% | AA30: 1516000 | AB30: 385 | AC30: 1000000 | AF30: Mostly self-funded | AG30: 1068000 | AH30: 31000 | AJ30: >12 Months | AK30: Insufficient | AL30: Miniimal | AM30: High | AN30: Full democracy | AO30: Central gov. | AP30: Unprepared | AQ30: Adequate | AR30: Established scientific basis | AS30: Poor | AT30: Frequent | AU30: 6-10 Years | AV30: 96 | AW30: Improved | AX30: =VLOOKUP(AW30,Metric_Codes!$C$91:$D$95,2,FALSE) -> 4 | AY30: Low | AZ30: 6-10 Years | BA30: 96 | BB30: Improved | BC30: =VLOOKUP(BB30,Metric_Codes!$C$91:$D$95,2,FALSE) -> 4 | BD30: Much improved | BE30: =VLOOKUP(BD30,Metric_Codes!$C$91:$D$95,2,FALSE) -> 5 | BF30: =(BC30+BE30)/2 -> 4.5 | BG30: Low | BH30: Negligible | BI30: 23 | BJ30: recovery slowed by Great Depression
A31: 30 | B31: 1939 China Floods | C31: China | D31: CHN | E31: Flood | F31: Riverine Flood | G31: Climate | H31: 1939 | I31: Assumption | J31: Catastrophic damage | K31: Tientsin | L31: Local | M31: 667070000 | N31: C: Service with Industry (service 50-67% and Industry >25%) | O31: Mixed | P31: 67.3 | Q31: Upper middle | R31: Contracting | S31: -0.2727 | T31: 89.52 | U31: 990 | V31: 0.643 | W31: 38.6 | X31: 39 | Z31: 60-80% | AA31: 1400000 | AB31: 20000 | AD31: 3000000 | AE31: 0.0044972791 | AF31: Self-funded | AK31: Totally insufficient | AL31: Miniimal | AM31: High | AN31: Authoritarian | AO31: Central gov. | AP31: Completely unprepared | AQ31: Inadequate | AR31: Established scientific basis | AS31: Poor | AT31: Frequent | AU31: 11-20 Years | AV31: 180 | AW31: Same | AX31: =VLOOKUP(AW31,Metric_Codes!$C$91:$D$95,2,FALSE) -> 3 | AY31: Low | AZ31: 11-20 Years | BA31: 144 | BB31: Same | BC31: =VLOOKUP(BB31,Metric_Codes!$C$91:$D$95,2,FALSE) -> 3 | BD31: Improved | BE31: =VLOOKUP(BD31,Metric_Codes!$C$91:$D$95,2,FALSE) -> 4 | BF31: =(BC31+BE31)/2 -> 3.5 | BG31: Low | BH31: Negligible | BI31: 3 | BJ31: recovery slowed by 2nd WW, and Communist Great leap Forward
A32: 31 | B32: 1949 Guatemala Floods | C32: Guatemala | D32: GTM | E32: Flood | F32: Riverine Flood | G32: Climate | H32: 1949 | I32: Assumption | J32: Extremely catastrophic damage | K32: Pacific coast | L32: Regional | M32: 4210747 | O32: Service-Oriented | P32: 62.6 | Q32: Upper middle | R32: Growing | S32: 0.043 | T32: 247.84 | U32: 3230 | V32: 0.467 | W32: 48.3 | X32: 27 | Y32: <0.5% | Z32: 20-40% | AA32: 15000 | AB32: 1000 | AC32: 20000 | AF32: Mostly self-funded | AK32: Insufficient | AL32: Miniimal | AM32: High | AN32: Hybrid regime | AO32: Central gov. | AP32: Completely unprepared | AQ32: Inadequate | AR32: Limited scientific basis | AS32: Poor | AT32: Frequent | AU32: 1-2 Years | AV32: 18 | AW32: Same | AX32: =VLOOKUP(AW32,Metric_Codes!$C$91:$D$95,2,FALSE) -> 3 | AY32: Low | AZ32: 3-5 Years | BA32: 36 | BB32: Same | BC32: =VLOOKUP(BB32,Metric_Codes!$C$91:$D$95,2,FALSE) -> 3 | BD32: Same | BE32: =VLOOKUP(BD32,Metric_Codes!$C$91:$D$95,2,FALSE) -> 3 | BF32: =(BC32+BE32)/2 -> 3 | BG32: Low | BH32: Negligible | BI32: 4 | BJ32: discepancy in number of fatalities EMDAT 40,000
A33: 32 | B33: 1953 North Kyushu Flood | C33: Japan | D33: JPN | E33: Flood | F33: Riverine Flood | G33: Climate | H33: 1953 | I33: Kamamoto city 70% inundated; 2.5-3 m | J33: Catastrophic damage | K33: Northern Kyushu -Kumamoto/Fukuoka | L33: Regional | M33: 92500572 | N33: B: Service-Oriented Economy (67-75% of economy based on services) | O33: Service-Oriented | P33: 72.1 | Q33: High | R33: Growing | S33: 0.1204 | T33: 479 | U33: 19620 | V33: 0.876 | W33: 32.1 | X33: 73 | Y33: ~1% | Z33: 20-40% | AA33: 1991000 | AB33: 759 | AD33: 1886760 | AE33: 0.020397279 | AF33: Mostly self-funded | AJ33: >12 Months | AK33: Sufficient | AL33: Miniimal | AM33: High | AN33: Full democracy | AO33: Central gov. | AP33: Somewhat prepared | AQ33: Adequate | AR33: Established scientific basis | AS33: Poor | AT33: Frequent | AU33: 1-2 Years | AV33: 18 | AW33: Same | AX33: =VLOOKUP(AW33,Metric_Codes!$C$91:$D$95,2,FALSE) -> 3 | AY33: Low | AZ33: 1-2 Years | BA33: 18 | BB33: Same | BC33: =VLOOKUP(BB33,Metric_Codes!$C$91:$D$95,2,FALSE) -> 3 | BD33: Improved | BE33: =VLOOKUP(BD33,Metric_Codes!$C$91:$D$95,2,FALSE) -> 4 | BF33: =(BC33+BE33)/2 -> 3.5 | BG33: Low | BH33: Negligible | BI33: 4 | BJ33: EMDAT 2,566 fatalities
A34: 33 | B34: 1953 North Sea Flood | C34: Netherlands | D34: NLD | E34: Flood | F34: Coastal Flood | G34: Climate | H34: 1953 | I34: Max water 5.6 m AMSL; 50% Netherlands <1 m AMSL | J34: Catastrophic damage | K34: South East coast | L34: Regional | M34: 11486631 | N34: A: Service-Dominated Economy (more than 75% of economy based on services) | O34: Service-Dominated | P34: 76.8 | Q34: High | R34: Stable | S34: 0.003 | T34: 1068.78 | U34: 18730 | V34: 0.857 | W34: 28.2 | X34: 82 | Y34: <3% | Z34: 0-20% | AA34: 300000 | AB34: 1836 | AC34: 72000 | AD34: 300000 | AE34: 0.026117318 | AF34: Mostly external | AJ34: <12 Months | AK34: Sufficient | AL34: Major | AM34: High | AN34: Full democracy | AO34: Central gov. | AP34: Well prepared | AQ34: Adequate | AR34: Established scientific basis | AS34: Good | AT34: Infrequent | AU34: 6-11 Months | AV34: 9 | AW34: Improved | AX34: =VLOOKUP(AW34,Metric_Codes!$C$91:$D$95,2,FALSE) -> 4 | AY34: Medium | AZ34: 1-2 Years | BA34: 18 | BB34: Improved | BC34: =VLOOKUP(BB34,Metric_Codes!$C$91:$D$95,2,FALSE) -> 4 | BD34: Much improved | BE34: =VLOOKUP(BD34,Metric_Codes!$C$91:$D$95,2,FALSE) -> 5 | BF34: =(BC34+BE34)/2 -> 4.5 | BG34: Medium | BH34: Important | BI34: 12 | BJ34: Also UK with similar recovery speed and quality
A35: 34 | B35: 1954 Iran Summer Floods | C35: Iran, Islamic Rep. | D35: IRN | E35: Flood | F35: Flash Flood | G35: Climate | H35: 1954 | I35: Assumption | J35: Catastrophic damage | K35: Farahzad, Tehran | L35: Local | M35: 21906903 | N35: F: Industry with Service (Industry and Service both 33-50%) | O35: Mixed | P35: 51.1 | Q35: Upper middle | R35: Growing | S35: 0.1148 | T35: 191.68 | U35: 7390 | V35: 0.707 | W35: 40 | X35: 28 | Y35: <0.3 | Z35: 40-60% | AB35: 2150 | AF35: Mostly self-funded | AK35: Insufficient | AL35: Miniimal | AM35: High | AN35: Authoritarian | AO35: Central gov. | AP35: Unprepared | AQ35: Inadequate | AR35: Limited scientific basis | AS35: Poor | AT35: Frequent | AU35: 6-11 Months | AV35: 9 | AW35: Same | AX35: =VLOOKUP(AW35,Metric_Codes!$C$91:$D$95,2,FALSE) -> 3 | AY35: Low | AZ35: 1-2 Years | BA35: 18 | BB35: Same | BC35: =VLOOKUP(BB35,Metric_Codes!$C$91:$D$95,2,FALSE) -> 3 | BD35: Same | BE35: =VLOOKUP(BD35,Metric_Codes!$C$91:$D$95,2,FALSE) -> 3 | BF35: =(BC35+BE35)/2 -> 3 | BG35: Low | BH35: Negligible | BI35: 2 | BJ35: period of political turmoil
A36: 35 | B36: 1962 Rubi Flood | C36: Spain | D36: ESP | E36: Flood | F36: Flash Flood | G36: Climate | H36: 1962 | I36: 200cm rainfall in <2hr; <1:200 yr | J36: Extremely catastrophic damage | K36: Lobregat, Barcelona | L36: Local | M36: 31023366 | N36: A: Service-Dominated Economy (more than 75% of economy based on services) | O36: Industry with Service | P36: 65.7 | Q36: High | R36: Growing | S36: 0.0995 | T36: 520.21 | U36: 13530 | V36: 0.754 | W36: 36.2 | X36: 58 | Y36: <1% | Z36: 20-40% | AA36: 80000 | AB36: 815 | AF36: Mostly self-funded | AK36: Insufficient | AL36: Moderate | AM36: High | AN36: Full democracy | AO36: Central gov. | AP36: Unprepared | AQ36: Adequate | AR36: Established scientific basis | AS36: Mediocre | AT36: Occasional | AU36: 6-11 Months | AV36: 9 | AW36: Improved | AX36: =VLOOKUP(AW36,Metric_Codes!$C$91:$D$95,2,FALSE) -> 4 | AY36: Low | AZ36: 1-2 Years | BA36: 18 | BB36: Improved | BC36: =VLOOKUP(BB36,Metric_Codes!$C$91:$D$95,2,FALSE) -> 4 | BD36: Improved | BE36: =VLOOKUP(BD36,Metric_Codes!$C$91:$D$95,2,FALSE) -> 4 | BF36: =(BC36+BE36)/2 -> 4 | BG36: Low | BH36: Small | BI36: 4 | BJ36: big influx of immigrants from S America and N Africa
A37: 36 | B37: 1963 Landslide of the Vajont Dam | C37: Italy | D37: ITA | E37: Flood | F37: Riverine Flood | G37: Climate | H37: 1963 | I37: flood wave overtop dam in 250 m high wave | J37: Extremely catastrophic damage | K37: Piave Valley north Venice | L37: Local | M37: 51252000 | N37: A: Service-Dominated Economy (more than 75% of economy based on services) | O37: Industry-Oriented | P37: 62.2 | Q37: High | R37: Growing | S37: 0.062 | T37: 1126.02 | U37: 18330 | V37: 0.771 | W37: 35.4 | X37: 52 | Y37: <0.8 | Z37: 80-100% | AA37: 2000000 | AB37: 1917 | AC37: 1300000 | AD37: 1300000 | AE37: 0.025364864 | AF37: External | AJ37: >24 Months | AK37: Sufficient | AL37: Miniimal | AM37: High | AN37: Flawed democracy | AO37: Central gov. | AP37: Completely unprepared | AQ37: Inadequate | AR37: Limited scientific basis | AS37: Mediocre | AT37: Infrequent | AU37: 6-10 Years | AV37: 96 | AW37: Improved | AX37: =VLOOKUP(AW37,Metric_Codes!$C$91:$D$95,2,FALSE) -> 4 | AY37: Low | BB37: Worse | BC37: =VLOOKUP(BB37,Metric_Codes!$C$91:$D$95,2,FALSE) -> 2 | BD37: Much improved | BE37: =VLOOKUP(BD37,Metric_Codes!$C$91:$D$95,2,FALSE) -> 5 | BF37: =(BC37+BE37)/2 -> 3.5 | BG37: Medium | BH37: Negligible | BI37: 8 | BJ37: 80% of inhabitants killed survivors moved 50km to newly built village Vajont, Longarone, the town in path of tsunami, was rebuilt
A38: 37 | B38: 1966 Jordan Flood | C38: Jordan | D38: JOR | E38: Flood | F38: Flash Flood | G38: Climate | H38: 1966 | I38: 1:50 RP | J38: Catastrophic damage | K38: Ma'an | L38: Local | M38: 1265806 | O38: Industry-Oriented | P38: 66.5 | Q38: Upper middle | R38: Growing | S38: 0.2431 | T38: 519.89 | U38: 3850 | V38: 0.617 | W38: 33.7 | X38: 49 | Y38: 0 | Z38: 40-60% | AA38: 1400 | AB38: 259 | AC38: 2500 | AD38: 5792 | AE38: 0.0045757407 | AF38: Mostly self-funded | AK38: Insufficient | AL38: Miniimal | AM38: High | AN38: Authoritarian | AO38: Central gov. | AP38: Unprepared | AQ38: Inadequate | AR38: Limited scientific basis | AS38: Very poor | AT38: Frequent | AU38: 6-11 Months | AV38: 9 | AW38: Same | AX38: =VLOOKUP(AW38,Metric_Codes!$C$91:$D$95,2,FALSE) -> 3 | AY38: Low | AZ38: 1-2 Years | BA38: 18 | BB38: Same | BC38: =VLOOKUP(BB38,Metric_Codes!$C$91:$D$95,2,FALSE) -> 3 | BD38: Same | BE38: =VLOOKUP(BD38,Metric_Codes!$C$91:$D$95,2,FALSE) -> 3 | BF38: =(BC38+BE38)/2 -> 3 | BG38: Low | BH38: Negligible | BI38: 7 | BJ38: Poor urban planning, recent huge refugee problem
A39: 38 | B39: 1967 Lisbon Flood | C39: Portugal | D39: PRT | E39: Flood | F39: Flash Flood | G39: Climate | H39: 1967 | I39: >1:100 yr rainfall | J39: Extremely catastrophic damage | K39: Lisbon | L39: Local | M39: 8874520 | N39: A: Service-Dominated Economy (more than 75% of economy based on services) | O39: Service-Oriented | P39: 65.3 | Q39: High | R39: Growing | S39: 0.0754 | T39: 646.82 | U39: 11770 | V39: 0.732 | W39: 35.5 | X39: 64 | Y39: <2% | Z39: 40-60% | AA39: 3000 | AB39: 462 | AD39: 1100 | AE39: 0.00012395037 | AF39: Mostly self-funded | AK39: Insufficient | AL39: Miniimal | AM39: High | AN39: Flawed democracy | AO39: Central gov. | AP39: Unprepared | AQ39: Adequate | AR39: Established scientific basis | AS39: Poor | AT39: Frequent | AU39: 6-11 Months | AV39: 9 | AW39: Same | AX39: =VLOOKUP(AW39,Metric_Codes!$C$91:$D$95,2,FALSE) -> 3 | AY39: Low | AZ39: 6-11 Months | BA39: 9 | BB39: Same | BC39: =VLOOKUP(BB39,Metric_Codes!$C$91:$D$95,2,FALSE) -> 3 | BD39: Same | BE39: =VLOOKUP(BD39,Metric_Codes!$C$91:$D$95,2,FALSE) -> 3 | BF39: =(BC39+BE39)/2 -> 3 | BG39: Low | BH39: Negligible | BI39: 5 | BJ39: Lack of information; 20,000 houses were destroyed. Officially, there were 462 dead, but the number may have reached 700. In the face of Salazar's apathy, 5,000 students helped the victims. A movement that marked a generatio
A40: 39 | B40: 1972 Seoul Kyonggi Flood | C40: Korea, Rep. | D40: KOR | E40: Flood | F40: Riverine Flood | G40: Climate | H40: 1972 | I40: Seoul 45cm rainfall | J40: Catastrophic damage | K40: Seoul; Kyonggi, Kangwon, North Chungchong | L40: Regional | M40: 33505406 | N40: C: Service with Industry (service 50-67% and Industry >25%) | O40: Mixed | P40: 72.3 | Q40: High | R40: Growing | S40: 0.0715 | T40: 323.6 | U40: 8260 | V40: 0.773 | W40: 31.6 | X40: 57 | Y40: <0.5% | Z40: 40-60% | AA40: 72800 | AB40: 672 | AC40: 326000 | AD40: 1126785 | AE40: 0.033629946 | AF40: Mostly self-funded | AK40: Insufficient | AL40: Miniimal | AM40: High | AN40: Flawed democracy[a] | AO40: Central gov. | AP40: Somewhat prepared | AQ40: Inadequate | AR40: Limited scientific basis | AS40: Poor | AT40: Frequent | AU40: <6 Months | AV40: 3 | AW40: Same | AX40: =VLOOKUP(AW40,Metric_Codes!$C$91:$D$95,2,FALSE) -> 3 | AY40: Low | AZ40: 6-11 Months | BA40: 6 | BB40: Same | BC40: =VLOOKUP(BB40,Metric_Codes!$C$91:$D$95,2,FALSE) -> 3 | BD40: Same | BE40: =VLOOKUP(BD40,Metric_Codes!$C$91:$D$95,2,FALSE) -> 3 | BF40: =(BC40+BE40)/2 -> 3 | BG40: Low | BH40: Negligible | BI40: 6 | BJ40: Floods on Han River every 5 years; flood control, especially dams, has reduced risk; people cope with trafiic jams and loss of water supply
...

Sheet Metric_Definitions
A1: Metadata for metrics in the database
A2: Category | B2: Metric | C2: Description | D2: Value Year (where applicable) | E2: Value Scale | F2: Units | G2: Source (where common)
A3: Disaster Profile | B3: Disaster Name | C3: Disaster name as titled on Wikipedia | D3: - | E3: - | F3: - | G3: Wikipedia
B4: Country | C4: Disaster country as defined by the World Bank classification; where event spans multiple countries, only the worst-affected country has been chosen | D4: - | E4: - | F4: - | G4: World Bank
B5: ISO | C5: ISO 3166-1 alpha-3 - three letter country codes | D5: - | E5: - | F5: - | G5: ISO 3166 standard
B6: Disaster Type | C6: Disaster type: flood, storm, earthquake | D6: - | E6: - | F6: - | G6: EM-DAT
B7: Disaster Subtype | C7: Disaster sub-type | D7: - | E7: - | F7: - | G7: EM-DAT
B8: Type | C8: Climate (Weather related) or Geophysical | G8: EM-DAT | K8: Climate or Geophysical
B9: Year | C9: Year of event; where events (primarily floods) occur across multiple years, use the start year | D9: - | E9: - | F9: - | G9: EM-DAT | K9: Geophysical
B10: Magnitude | C10: Dependent on event type | D10: - | E10: - | F10: - | G10: EM-DAT
B11: Hazard Magnitude Normalised | F11: 1-4 rating scale
B12: Locus | C12: Most severely impacted administrative area | D12: - | E12: - | F12: - | G12: -
B13: Scale | D13: - | E13: - | F13: 1-3 rating scale
A14: Antecedent conditions | B14: Population | C14: Total national population | D14: Event Year | E14: National | F14: People | G14: World Bank: https://data.worldbank.org/indicator/sp.pop.totl
B15: Economy Type | C15: Orientation of economy based on proportion of GDP produced by services, industrial, and agricultural sectors | D15: 2018 | E15: National | F15: - | G15: Lookup based on country ISO; CCRS classification, based on proportion OEM GDP - manual overwrite where neccessary
B16: Economy 2 | C16: As Economy Type but with specific percentages defined by World Bank World Development Indicators (see worksheet WB–Economy) | D16: 2018 | E16: National | F16: % | G16: https://wdi.worldbank.org/table/4.2
B17: Economic Freedom | C17: The Economist Democracy Index 2018 https://en.wikipedia.org/wiki/Democracy_Index (see worksheet Countries) | D17: 2018 | E17: National | F17: %
B18: Economic Growth cat | C18: Categorization of country based on whether the GDP Growth is Stable, Growing or Contracting | D18: Event Year | E18: National | F18: 3 Categories
B19: Income Group | C19: According to the World Bank Country Classification | D19: Event Year | E19: National | F19: - | G19: World Bank: https://datahelpdesk.worldbank.org/knowledgebase/articles/906519-world-bank-country-and-lending-groups
B20: GDP Growth | C20: Measure of the annual real economic growth rate | D20: Event Year | E20: National | F20: % | G20: World Bank: https://data.worldbank.org/indicator/NY.GDP.MKTP.KD.ZG?locations=BD
B21: GDP per Capita | C21: Measure of the total output of a country that divides GDP by total population | D21: Event Year | E21: National | F21: US$ | G21: World Bank: https://data.worldbank.org/indicator/ny.gdp.pcap.cd
B22: GNI per Capita | C22: The dollar value of a country's final income in a year, divided by its population. It reflects the average income of a country's citizens. | D22: Event Year | E22: National | F22: US$ | G22: World Bank: https://data.worldbank.org/indicator/ny.gnp.pcap.pp.cd
B23: IHDI Value | C23: The IHDI combines a country's average achievements in health, education and income with how those achievements are distributed among country's population by “discounting” each dimension's average value according to its level ofinequality. | D23: 2017 | E23: National | F23: 0-1 index | G23: United Nations: http://hdr.undp.org/en/composite/IHDI
A24: Load | B24: Gini Coefficient | C24: Inequality/ wealth distribution of residents within country | D24: Most Recent | E24: National | F24: 0-100 index | G24: World Bank: https://data.worldbank.org/indicator/SI.POV.GINI
B25: Corrupt. Index | C25: Corruption perceptions index: higher the score the less corruption 100=zero corruption | D25: 2018 | E25: National | F25: 0-100 index | G25: Transparency International: https://www.transparency.org/research/cpi/overview
B26: Non-Life Insurance Penetration | C26: Insurance premiums as a proportion of GDP | D26: Event Year | E26: National | F26: % | G26: Sigma Swiss Re (data aquired by CCRS, visible on sigma explorer http://www.sigma-explorer.com/ but cant be exported)
B27: Damage Severity | C27: Proportional damage/destruction of physical building stock/infrastructure | D27: - | E27: Locus | F27: 1-5 rating scale | G27: -
B28: Economic Loss | C28: A value of all economic losses directly or indirectly related to the disaster | D28: 2018 | E28: National | F28: 000 US$ | G28: EM-DAT
B29: Fatalities | C29: Number of people who lost their life as a result of the event | D29: - | E29: National | F29: People | G29: EM-DAT
A30: Resourcing | B30: Displaced | C30: Number of people whose house is destroyed or heavily damaged and therefore need shelter after the event | D30: - | E30: National | F30: People | G30: EM-DAT
B31: Affected Population | C31: People requiring immediate assistance during an emergency situation. Conveys the extent, impact, or severity of a disaster in non-spatial terms. | D31: - | E31: National | F31: People | G31: EM-DAT
